Traceback (most recent call last):
  File "/opt/hostedtoolcache/Python/3.11.13/x64/lib/python3.11/site-packages/jupyter_core/utils/__init__.py", line 154, in wrapped
    asyncio.get_running_loop()
RuntimeError: no running event loop

During handling of the above exception, another exception occurred:

Traceback (most recent call last):
  File "/opt/hostedtoolcache/Python/3.11.13/x64/lib/python3.11/site-packages/jupyter_cache/executors/utils.py", line 58, in single_nb_execution
    executenb(
  File "/opt/hostedtoolcache/Python/3.11.13/x64/lib/python3.11/site-packages/nbclient/client.py", line 1319, in execute
    return NotebookClient(nb=nb, resources=resources, km=km, **kwargs).execute()
           ^^^^^^^^^^^^^^^^^^^^^^^^^^^^^^^^^^^^^^^^^^^^^^^^^^^^^^^^^^^^^^^^^^^^^
  File "/opt/hostedtoolcache/Python/3.11.13/x64/lib/python3.11/site-packages/jupyter_core/utils/__init__.py", line 158, in wrapped
    return loop.run_until_complete(inner)
           ^^^^^^^^^^^^^^^^^^^^^^^^^^^^^^
  File "/opt/hostedtoolcache/Python/3.11.13/x64/lib/python3.11/asyncio/base_events.py", line 654, in run_until_complete
    return future.result()
           ^^^^^^^^^^^^^^^
  File "/opt/hostedtoolcache/Python/3.11.13/x64/lib/python3.11/site-packages/nbclient/client.py", line 709, in async_execute
    await self.async_execute_cell(
  File "/opt/hostedtoolcache/Python/3.11.13/x64/lib/python3.11/site-packages/nbclient/client.py", line 1062, in async_execute_cell
    await self._check_raise_for_error(cell, cell_index, exec_reply)
  File "/opt/hostedtoolcache/Python/3.11.13/x64/lib/python3.11/site-packages/nbclient/client.py", line 918, in _check_raise_for_error
    raise CellExecutionError.from_cell_and_msg(cell, exec_reply_content)
nbclient.exceptions.CellExecutionError: An error occurred while executing the following cell:
------------------
np.random.seed(123)

losses = np.random.normal(size=(batch_size,))
weights = compute_sample_weight(losses)

print(weights[np.argsort(losses)])
------------------


[31m---------------------------------------------------------------------------[39m
[31mAssertionError[39m                            Traceback (most recent call last)
[36mCell[39m[36m [39m[32mIn[4][39m[32m, line 4[39m
[32m      1[39m np.random.seed([32m123[39m)
[32m      3[39m losses = np.random.normal(size=(batch_size,))
[32m----> [39m[32m4[39m weights = [43mcompute_sample_weight[49m[43m([49m[43mlosses[49m[43m)[49m
[32m      6[39m [38;5;28mprint[39m(weights[np.argsort(losses)])

[36mFile [39m[32m/opt/hostedtoolcache/Python/3.11.13/x64/lib/python3.11/site-packages/deshift/_src/spectral_risk.py:29[39m, in [36mmake_spectral_risk_measure.<locals>.max_oracle[39m[34m(losses)[39m
[32m     28[39m [38;5;28;01mdef[39;00m[38;5;250m [39m[34mmax_oracle[39m(losses):
[32m---> [39m[32m29[39m     [38;5;28;01massert[39;00m torch.is_tensor(losses), [33m"[39m[33m`losses` must be a PyTorch tensor[39m[33m"[39m
[32m     30[39m     [38;5;28;01mwith[39;00m torch.no_grad():
[32m     31[39m         device = losses.get_device()

[31mAssertionError[39m: `losses` must be a PyTorch tensor

